<?xml version="1.0"?>
<robot name="my_robot" xmlns:xacro="http://www.ros.org/wiki/xacro">

  <!-- Параметры -->
  <xacro:property name="base_length" value="0.4"/>
  <xacro:property name="base_width" value="0.4"/>
  <xacro:property name="base_height" value="0.2"/>

  <xacro:property name="wheel_radius" value="0.03"/>
  <xacro:property name="mass_base" value="5.00"/>
  <xacro:property name="wheel_width" value="0.02"/>
  <xacro:property name="wheel_y_offset" value="0.21"/>

  <material name="robot_blue">
    <color rgba="0.2 0.4 1 1"/>
  </material>
  <material name="robot_gray">
    <color rgba="0.7 0.7 0.7 1"/>
  </material>

  <!-- База -->
  <link name="base_link">
    <visual>
      <geometry>
        <box size="${base_length} ${base_width} ${base_height}"/>
      </geometry>
    <material name="robot_gray"/>
    </visual>
    <collision>
      <geometry>
        <box size="${base_length} ${base_width} ${base_height}"/>
      </geometry>
    </collision>

    <inertial>
      <origin xyz="0 0 0" rpy="0 0 0"/>
      <mass value="${mass_base}"/>
      <inertia
        ixx="0.0208"
        ixy="0.0"
        ixz="0.0"
        iyy="0.0283"
        iyz="0.0"
        izz="0.0417"/>
    </inertial>
  </link>

  <!-- Макрос колеса -->
  <xacro:macro name="wheel" params="name y_offset">
    <link name="${name}">
      <visual>
        <geometry>
          <cylinder radius="${wheel_radius}" length="${wheel_width}"/>
        </geometry>
      </visual>

      <collision>
        <geometry>
          <cylinder radius="${wheel_radius}" length="${wheel_width}"/>
        </geometry>
      </collision>

      <inertial>
        <origin xyz="0 0 0" rpy="0 0 0"/>
        <mass value="0.2"/>
        <inertia
          ixx="0.00013"
          ixy="0.0"
          ixz="0.0"
          iyy="0.00013"
          iyz="0.0"
          izz="0.00025"/>
      </inertial>
    </link>

    <joint name="${name}_joint" type="continuous">
      <parent link="base_link"/>
      <child link="${name}"/>
      <origin xyz="0 ${y_offset} ${- base_height/2 + wheel_radius/2}" rpy="0 1.57 1.57"/>
      <axis xyz="0 0 1"/>
    </joint>
  </xacro:macro>


  <xacro:macro name="range_sensor_mount" params="name x y z roll pitch yaw">
  <link name="${name}">
    <visual>
      <geometry>
        <box size="0.02 0.02 0.02"/>
      </geometry>
      <material name="robot_blue"/>
    </visual>
  </link>

  <joint name="${name}_joint" type="fixed">
    <parent link="base_link"/>
    <child link="${name}"/>
    <origin xyz="${x} ${y} ${z}" rpy="${roll} ${pitch} ${yaw}"/>
  </joint>
  </xacro:macro>

  <!-- Support wheel -->
  <xacro:macro name="support_wheel" params="name x y z">
  <link name="${name}">
    <visual>
      <geometry>
        <sphere radius="0.03"/>
      </geometry>
    </visual>
    <collision>
      <geometry>
        <sphere radius="0.03"/>
      </geometry>
    </collision>
  </link>

  <joint name="${name}_joint" type="fixed">
    <parent link="base_link"/>
    <child link="${name}"/>
    <origin  xyz="${x} ${y} ${z}" rpy="0 0 0"/>
  </joint>
  </xacro:macro>

  <!-- Sensors -->
  <xacro:range_sensor_mount name="range_front" x="0.21" y="0.0" z="0.05" roll="0" pitch="0" yaw="0"/>
  <xacro:range_sensor_mount name="range_left"  x="0.00" y="0.21" z="0.05" roll="0" pitch="0" yaw="1.5708"/>
  <xacro:range_sensor_mount name="range_right" x="0.00" y="-0.21" z="0.05" roll="0" pitch="0" yaw="-1.5708"/>

  <!-- Колёса -->
  <xacro:wheel name="left_wheel" y_offset="${wheel_y_offset}"/>
  <xacro:wheel name="right_wheel" y_offset="-${wheel_y_offset}"/>
  <xacro:support_wheel name="front_support_wheel" x="${wheel_y_offset/2}" y="0" z="${- base_height/2 + wheel_radius/2}"/>
  <xacro:support_wheel name="back_support_wheel" x="${- wheel_y_offset/2}" y="0" z="${- base_height/2 + wheel_radius/2}"/>

  <gazebo>
    <plugin
        filename="gz-sim-diff-drive-system"
        name="gz::sim::systems::DiffDrive">

      <left_joint>left_wheel_joint</left_joint>
      <right_joint>right_wheel_joint</right_joint>

      <wheel_separation>0.42</wheel_separation>
      <wheel_radius>0.03</wheel_radius>

      <odom_publish_frequency>50</odom_publish_frequency>

      <topic>model/diff_drive/cmd_vel</topic>
      <odom_topic>model/diff_drive/odometry</odom_topic>
      <tf_topic>model/diff_drive/pose</tf_topic>

      <frame_id>diff_drive/odom</frame_id>
      <child_frame_id>base_link</child_frame_id>
    </plugin>
    <plugin
      filename="gz-sim-joint-state-publisher-system"
      name="gz::sim::systems::JointStatePublisher">
      <topic>/world/empty/model/diff_drive/joint_state</topic>
    </plugin>
    <plugin
      filename="gz-sim-pose-publisher-system"
      name="gz::sim::systems::PosePublisher">
      <publish_link_pose>true</publish_link_pose>
      <use_pose_vector_msg>true</use_pose_vector_msg>
      <static_publisher>true</static_publisher>
      <static_update_frequency>1</static_update_frequency>
    </plugin>
  </gazebo>

</robot>

